[2023-10-17T14:52:18.760+0100] {taskinstance.py:1159} INFO - Dependencies all met for dep_context=non-requeueable deps ti=<TaskInstance: stores_pipeline.grouping.groupby_location manual__2023-10-17T13:52:02.690838+00:00 [queued]>
[2023-10-17T14:52:18.763+0100] {taskinstance.py:1159} INFO - Dependencies all met for dep_context=requeueable deps ti=<TaskInstance: stores_pipeline.grouping.groupby_location manual__2023-10-17T13:52:02.690838+00:00 [queued]>
[2023-10-17T14:52:18.763+0100] {taskinstance.py:1361} INFO - Starting attempt 1 of 1
[2023-10-17T14:52:18.767+0100] {taskinstance.py:1382} INFO - Executing <Task(PythonOperator): grouping.groupby_location> on 2023-10-17 13:52:02.690838+00:00
[2023-10-17T14:52:18.769+0100] {standard_task_runner.py:57} INFO - Started process 58890 to run task
[2023-10-17T14:52:18.771+0100] {standard_task_runner.py:84} INFO - Running: ['airflow', 'tasks', 'run', 'stores_pipeline', 'grouping.groupby_location', 'manual__2023-10-17T13:52:02.690838+00:00', '--job-id', '353', '--raw', '--subdir', 'DAGS_FOLDER/stores_pipeline.py', '--cfg-path', '/var/folders/_3/bj8r7kz51nz4g7hl_dpr6jdw0000gn/T/tmpgfiox1g7']
[2023-10-17T14:52:18.772+0100] {standard_task_runner.py:85} INFO - Job 353: Subtask grouping.groupby_location
[2023-10-17T14:52:18.787+0100] {task_command.py:416} INFO - Running <TaskInstance: stores_pipeline.grouping.groupby_location manual__2023-10-17T13:52:02.690838+00:00 [running]> on host 192.168.1.112
[2023-10-17T14:52:18.802+0100] {taskinstance.py:1662} INFO - Exporting env vars: AIRFLOW_CTX_DAG_OWNER='workflow' AIRFLOW_CTX_DAG_ID='stores_pipeline' AIRFLOW_CTX_TASK_ID='grouping.groupby_location' AIRFLOW_CTX_EXECUTION_DATE='2023-10-17T13:52:02.690838+00:00' AIRFLOW_CTX_TRY_NUMBER='1' AIRFLOW_CTX_DAG_RUN_ID='manual__2023-10-17T13:52:02.690838+00:00'
[2023-10-17T14:52:18.806+0100] {logging_mixin.py:151} WARNING - /Users/b/airflow/dags/stores_pipeline.py:147 FutureWarning: Passing literal json to 'read_json' is deprecated and will be removed in a future version. To read from a literal string, wrap it in a 'StringIO' object.
[2023-10-17T14:52:18.815+0100] {taskinstance.py:1937} ERROR - Task failed with exception
Traceback (most recent call last):
  File "/Users/b/airflow/venv/lib/python3.11/site-packages/airflow/operators/python.py", line 192, in execute
    return_value = self.execute_callable()
                   ^^^^^^^^^^^^^^^^^^^^^^^
  File "/Users/b/airflow/venv/lib/python3.11/site-packages/airflow/operators/python.py", line 209, in execute_callable
    return self.python_callable(*self.op_args, **self.op_kwargs)
           ^^^^^^^^^^^^^^^^^^^^^^^^^^^^^^^^^^^^^^^^^^^^^^^^^^^^^
  File "/Users/b/airflow/dags/stores_pipeline.py", line 149, in groupby_location
    region_df = df.groupby('Store_Location').agg({
                ^^^^^^^^^^^^^^^^^^^^^^^^^^^^^^^^^^
  File "/Users/b/airflow/venv/lib/python3.11/site-packages/pandas/core/groupby/generic.py", line 1442, in aggregate
    result = op.agg()
             ^^^^^^^^
  File "/Users/b/airflow/venv/lib/python3.11/site-packages/pandas/core/apply.py", line 175, in agg
    return self.agg_dict_like()
           ^^^^^^^^^^^^^^^^^^^^
  File "/Users/b/airflow/venv/lib/python3.11/site-packages/pandas/core/apply.py", line 406, in agg_dict_like
    return self.agg_or_apply_dict_like(op_name="agg")
           ^^^^^^^^^^^^^^^^^^^^^^^^^^^^^^^^^^^^^^^^^^
  File "/Users/b/airflow/venv/lib/python3.11/site-packages/pandas/core/apply.py", line 1388, in agg_or_apply_dict_like
    result_index, result_data = self.compute_dict_like(
                                ^^^^^^^^^^^^^^^^^^^^^^^
  File "/Users/b/airflow/venv/lib/python3.11/site-packages/pandas/core/apply.py", line 479, in compute_dict_like
    results = [
              ^
  File "/Users/b/airflow/venv/lib/python3.11/site-packages/pandas/core/apply.py", line 480, in <listcomp>
    getattr(obj._gotitem(key, ndim=1), op_name)(how, **kwargs)
  File "/Users/b/airflow/venv/lib/python3.11/site-packages/pandas/core/groupby/generic.py", line 252, in aggregate
    ret = self._aggregate_multiple_funcs(func, *args, **kwargs)
          ^^^^^^^^^^^^^^^^^^^^^^^^^^^^^^^^^^^^^^^^^^^^^^^^^^^^^
  File "/Users/b/airflow/venv/lib/python3.11/site-packages/pandas/core/groupby/generic.py", line 357, in _aggregate_multiple_funcs
    results[key] = self.aggregate(func, *args, **kwargs)
                   ^^^^^^^^^^^^^^^^^^^^^^^^^^^^^^^^^^^^^
  File "/Users/b/airflow/venv/lib/python3.11/site-packages/pandas/core/groupby/generic.py", line 244, in aggregate
    return getattr(self, func)(*args, **kwargs)
           ^^^^^^^^^^^^^^^^^^^
  File "/Users/b/airflow/venv/lib/python3.11/site-packages/pandas/core/groupby/groupby.py", line 1308, in __getattr__
    raise AttributeError(
AttributeError: 'SeriesGroupBy' object has no attribute 'Coles_StoreID'
[2023-10-17T14:52:18.821+0100] {taskinstance.py:1400} INFO - Marking task as FAILED. dag_id=stores_pipeline, task_id=grouping.groupby_location, execution_date=20231017T135202, start_date=20231017T135218, end_date=20231017T135218
[2023-10-17T14:52:18.824+0100] {standard_task_runner.py:104} ERROR - Failed to execute job 353 for task grouping.groupby_location ('SeriesGroupBy' object has no attribute 'Coles_StoreID'; 58890)
[2023-10-17T14:52:18.833+0100] {local_task_job_runner.py:228} INFO - Task exited with return code 1
[2023-10-17T14:52:18.839+0100] {taskinstance.py:2778} INFO - 0 downstream tasks scheduled from follow-on schedule check
