[2023-10-17T14:50:19.170+0100] {taskinstance.py:1159} INFO - Dependencies all met for dep_context=non-requeueable deps ti=<TaskInstance: stores_pipeline.grouping.groupby_location manual__2023-10-17T13:50:04.783097+00:00 [queued]>
[2023-10-17T14:50:19.172+0100] {taskinstance.py:1159} INFO - Dependencies all met for dep_context=requeueable deps ti=<TaskInstance: stores_pipeline.grouping.groupby_location manual__2023-10-17T13:50:04.783097+00:00 [queued]>
[2023-10-17T14:50:19.172+0100] {taskinstance.py:1361} INFO - Starting attempt 1 of 1
[2023-10-17T14:50:19.176+0100] {taskinstance.py:1382} INFO - Executing <Task(PythonOperator): grouping.groupby_location> on 2023-10-17 13:50:04.783097+00:00
[2023-10-17T14:50:19.178+0100] {standard_task_runner.py:57} INFO - Started process 58560 to run task
[2023-10-17T14:50:19.180+0100] {standard_task_runner.py:84} INFO - Running: ['airflow', 'tasks', 'run', 'stores_pipeline', 'grouping.groupby_location', 'manual__2023-10-17T13:50:04.783097+00:00', '--job-id', '341', '--raw', '--subdir', 'DAGS_FOLDER/stores_pipeline.py', '--cfg-path', '/var/folders/_3/bj8r7kz51nz4g7hl_dpr6jdw0000gn/T/tmpj1l6swzl']
[2023-10-17T14:50:19.182+0100] {standard_task_runner.py:85} INFO - Job 341: Subtask grouping.groupby_location
[2023-10-17T14:50:19.197+0100] {task_command.py:416} INFO - Running <TaskInstance: stores_pipeline.grouping.groupby_location manual__2023-10-17T13:50:04.783097+00:00 [running]> on host 192.168.1.112
[2023-10-17T14:50:19.214+0100] {taskinstance.py:1662} INFO - Exporting env vars: AIRFLOW_CTX_DAG_OWNER='workflow' AIRFLOW_CTX_DAG_ID='stores_pipeline' AIRFLOW_CTX_TASK_ID='grouping.groupby_location' AIRFLOW_CTX_EXECUTION_DATE='2023-10-17T13:50:04.783097+00:00' AIRFLOW_CTX_TRY_NUMBER='1' AIRFLOW_CTX_DAG_RUN_ID='manual__2023-10-17T13:50:04.783097+00:00'
[2023-10-17T14:50:19.222+0100] {logging_mixin.py:151} WARNING - /Users/b/airflow/dags/stores_pipeline.py:147 FutureWarning: Passing literal json to 'read_json' is deprecated and will be removed in a future version. To read from a literal string, wrap it in a 'StringIO' object.
[2023-10-17T14:50:19.229+0100] {taskinstance.py:1937} ERROR - Task failed with exception
Traceback (most recent call last):
  File "/Users/b/airflow/venv/lib/python3.11/site-packages/airflow/operators/python.py", line 192, in execute
    return_value = self.execute_callable()
                   ^^^^^^^^^^^^^^^^^^^^^^^
  File "/Users/b/airflow/venv/lib/python3.11/site-packages/airflow/operators/python.py", line 209, in execute_callable
    return self.python_callable(*self.op_args, **self.op_kwargs)
           ^^^^^^^^^^^^^^^^^^^^^^^^^^^^^^^^^^^^^^^^^^^^^^^^^^^^^
  File "/Users/b/airflow/dags/stores_pipeline.py", line 149, in groupby_location
    region_df = df.groupby('Store_Location').agg({
                ^^^^^^^^^^^^^^^^^^^^^^^^^^^^^^^^^^
  File "/Users/b/airflow/venv/lib/python3.11/site-packages/pandas/core/groupby/generic.py", line 1442, in aggregate
    result = op.agg()
             ^^^^^^^^
  File "/Users/b/airflow/venv/lib/python3.11/site-packages/pandas/core/apply.py", line 175, in agg
    return self.agg_dict_like()
           ^^^^^^^^^^^^^^^^^^^^
  File "/Users/b/airflow/venv/lib/python3.11/site-packages/pandas/core/apply.py", line 406, in agg_dict_like
    return self.agg_or_apply_dict_like(op_name="agg")
           ^^^^^^^^^^^^^^^^^^^^^^^^^^^^^^^^^^^^^^^^^^
  File "/Users/b/airflow/venv/lib/python3.11/site-packages/pandas/core/apply.py", line 1388, in agg_or_apply_dict_like
    result_index, result_data = self.compute_dict_like(
                                ^^^^^^^^^^^^^^^^^^^^^^^
  File "/Users/b/airflow/venv/lib/python3.11/site-packages/pandas/core/apply.py", line 445, in compute_dict_like
    func = self.normalize_dictlike_arg(op_name, selected_obj, func)
           ^^^^^^^^^^^^^^^^^^^^^^^^^^^^^^^^^^^^^^^^^^^^^^^^^^^^^^^^
  File "/Users/b/airflow/venv/lib/python3.11/site-packages/pandas/core/apply.py", line 639, in normalize_dictlike_arg
    raise KeyError(f"Column(s) {list(cols)} do not exist")
KeyError: "Column(s) ['Store_Count'] do not exist"
[2023-10-17T14:50:19.235+0100] {taskinstance.py:1400} INFO - Marking task as FAILED. dag_id=stores_pipeline, task_id=grouping.groupby_location, execution_date=20231017T135004, start_date=20231017T135019, end_date=20231017T135019
[2023-10-17T14:50:19.238+0100] {standard_task_runner.py:104} ERROR - Failed to execute job 341 for task grouping.groupby_location ("Column(s) ['Store_Count'] do not exist"; 58560)
[2023-10-17T14:50:19.243+0100] {local_task_job_runner.py:228} INFO - Task exited with return code 1
[2023-10-17T14:50:19.249+0100] {taskinstance.py:2778} INFO - 0 downstream tasks scheduled from follow-on schedule check
